Workbook

Sheet Summary Snapshot
A1: DIGITAL PRODUCT SUMMARY SNAPSHOT | B1: 2025 | C1: 2025 | D1: 2026
A2: METRICS: | B2: Budget | C2: Actual | D2: Budget | F2: High level points:
A3: Total # of employees | C3: =B18 -> 2 | D3: =E18 -> 4 | F3: * $ 153,359 EHA cost of Anubhav (fees $142,173, Travel reimb $11,186 , total $153,359) was in RMM in 2025 budget not in GLobal Digital Products.
A4: Total # of EHA | C4: =C18 -> 1 | D4: =F18 -> 0 | F4: * A total sum of $ 80,177.$ 37,825 staff salary of Yashaswini Kumar and Sangeetha H M and 2 EHA of $ 16,060 were in Mediacal, 5 EHAs of $26,292 were in Health Com not in Digital Product.
A5: Digital Products | F5: * Total FTE staff increase =22. In India> 8, Bangaldesh > 6 , Indonesia> 7 and Nepal >1.
A6: Global Product | B6: =B532 -> 0 | C6: =C532 -> 0 | D6: ='Shared Summary by Dept_US$'!C14 -> 326653.49 | F6: * Total EHA Increase = 6. In India> 2, Bangaldesh > (-4) , Indonesia> 5 and Nepal> 3.
A7: Global Engineering | D7: ='Shared Summary by Dept_US$'!C15 -> 570322.05 | F7: * Software & subscription budget is maintained in US because of regulatory restriction in payment from India, INDO and BD
A8: Country Product | B8: =B133+B247+B361+B418+B589+B646 -> 1125183 | C8: =C133+C247+C361+C418+C589+C646 -> 935056.41 | D8: ='Shared Summary by Dept_US$'!C4+'Shared Summary by Dept_US$'!C5+'Shared Summary by Dept_US$'!C8+'Shared Summary by Dept_US$'!C11+'Shared Summary by Dept_US$'!C19 -> 895016.69 | F8: *Turn.io pricing increase not included post April 1st, 2026 - could be as high as $1.2M.
A9: Country Engineering | B9: =B190+B304+B475+B703 -> 837040 | C9: =C190+C304+C475+C703 -> 758116.78 | D9: ='Shared Summary by Dept_US$'!C6+'Shared Summary by Dept_US$'!C9+'Shared Summary by Dept_US$'!C12+'Shared Summary by Dept_US$'!C17+'Shared Summary by Dept_US$'!C20 -> 390274.27 | F9: * All new hires budget in India, INDO, BD and Nepal is from April 2026.
A10: Total Annual Budget | B10: =SUM(B6:B9) -> 1962223 | C10: =SUM(C6:C9) -> 1693173.2 | D10: =SUM(D6:D9) -> 2182266.5 | E10: =(D10-C10)/C10 -> 0.28886195 | F10: * 2025 Budget /Actual of Shared Platform Engineering / Software is reported under Engineering. In 2026, its budget /staff is moved to Global Digital Product.
F11: * Last year, out of 14 staff in Global Digital product , 8 staff joined over the year. Full 12 months salary is budgted in 2026
A13: # of People | B13: 2025 (Actual) | E13: 2026
B14: FTEs | C14: Contractors | D14: TOTAL | E14: FTEs | F14: Contractors | G14: TOTAL
A15: Global Product | B15: ='Staff Numbers'!B15 -> 14 | C15: ='Staff Numbers'!C15 -> 2 | D15: =SUM(B15:C15) -> 16 | E15: ='Staff Numbers'!F15 -> 5 | F15: ='Staff Numbers'!G15 -> 1 | G15: =SUM(E15:F15) -> 6 | H15: =E15-B15 -> -9 | I15: =F15-C15 -> -1
A16: Global Engineering | B16: ='Staff Numbers'!B16 -> 0 | C16: ='Staff Numbers'!C16 -> 0 | D16: =SUM(B16:C16) -> 0 | E16: ='Staff Numbers'!F16 -> 14 | F16: ='Staff Numbers'!G16 -> 1 | G16: =SUM(E16:F16) -> 15 | H16: =E16-B16 -> 14 | I16: =F16-C16 -> 1
A17: Country Product | B17: ='Staff Numbers'!B5+'Staff Numbers'!B6+'Staff Numbers'!B9+'Staff Numbers'!B12+'Staff Numbers'!B18+'Staff Numbers'!B20 -> 31 | C17: ='Staff Numbers'!C5+'Staff Numbers'!C6+'Staff Numbers'!C9+'Staff Numbers'!C12+'Staff Numbers'!C18+'Staff Numbers'!C20 -> 32 | D17: =SUM(B17:C17) -> 63 | E17: ='Staff Numbers'!F5+'Staff Numbers'!F6+'Staff Numbers'!F9+'Staff Numbers'!F12+'Staff Numbers'!F18+'Staff Numbers'!F20 -> 50 | F17: ='Staff Numbers'!G5+'Staff Numbers'!G6+'Staff Numbers'!G9+'Staff Numbers'!G12+'Staff Numbers'!G18+'Staff Numbers'!G20 -> 52 | G17: =SUM(E17:F17) -> 102 | H17: =E17-B17 -> 19 | I17: =F17-C17 -> 20
A18: Country Engineering | B18: ='Staff Numbers'!B7+'Staff Numbers'!B10+'Staff Numbers'!B13+'Staff Numbers'!B21 -> 2 | C18: ='Staff Numbers'!C7+'Staff Numbers'!C10+'Staff Numbers'!C13+'Staff Numbers'!C21 -> 1 | D18: =SUM(B18:C18) -> 3 | E18: ='Staff Numbers'!F7+'Staff Numbers'!F10+'Staff Numbers'!F13+'Staff Numbers'!F21 -> 4 | F18: ='Staff Numbers'!G7+'Staff Numbers'!G10+'Staff Numbers'!G13+'Staff Numbers'!G21 -> 0 | G18: =SUM(E18:F18) -> 4 | H18: =E18-B18 -> 2 | I18: =F18-C18 -> -1
A19: TOTAL | B19: =SUM(B15:B18) -> 47 | C19: =SUM(C15:C18) -> 35 | D19: =SUM(D15:D18) -> 82 | E19: =SUM(E15:E18) -> 73 | F19: =SUM(F15:F18) -> 54 | G19: =SUM(G15:G18) -> 127
A21: Analytical Review | B21: 2025 | C21: 2025 | D21: 2025 | E21: 2026
A22: Digital Product | B22: Budget | C22: Utilisation | D22: Variance | E22: Budget
A23: Salaries and Wages | B23: =SUBTOTAL(9,B24:B33) -> 1136023 | C23: =SUBTOTAL(9,C24:C33) -> 862831.9 | D23: =(C23-B23)/B23 -> -0.24048026 | E23: =SUBTOTAL(9,E24:E33) -> 1251050.8 | F23: =(E23-C23)/C23 -> 0.44993577 | J23: =E23/$E$75 -> 0.5732805
A24: Salaries and Wages | B24: =B82+B139+B196+B253+B310+B367+B424+B481+B538+B595+B652 -> 1121412 | C24: =C82+C139+C196+C253+C310+C367+C424+C481+C538+C595+C652 -> 855460.57 | D24: =(C24-B24) -> -265951.43 | E24: =SUMIF('Digital Product Summary by COA'!$C$3:$C$47,$A24,'Digital Product Summary by COA'!$E$3:$E$47) -> 1229549.1 | J24: =E24/$E$75 -> 0.56342755
A25: Gratuity & Bonus | B25: =B83+B140+B197+B254+B311+B368+B425+B482+B539+B596+B653 -> 14611 | C25: =C83+C140+C197+C254+C311+C368+C425+C482+C539+C596+C653 -> 6986.6873 | D25: =(C25-B25) -> -7624.3127 | E25: =SUMIF('Digital Product Summary by COA'!$C$3:$C$47,$A25,'Digital Product Summary by COA'!$E$3:$E$47) -> 21501.757 | J25: =E25/$E$75 -> 0.0098529472
A26: Staff Insurance | B26: =B84+B141+B198+B255+B312+B369+B426+B483+B540+B597+B654 -> 0 | C26: =C84+C141+C198+C255+C312+C369+C426+C483+C540+C597+C654 -> 384.63641 | D26: =(C26-B26) -> 384.63641 | E26: =SUMIF('Digital Product Summary by COA'!$C$3:$C$47,$A26,'Digital Product Summary by COA'!$E$3:$E$47) -> 0 | J26: =E26/$E$75 -> 0
A27: Internal meetings | B27: =B85+B142+B199+B256+B313+B370+B427+B484+B541+B598+B655 -> 0 | C27: =C85+C142+C199+C256+C313+C370+C427+C484+C541+C598+C655 -> 0 | D27: =(C27-B27) -> 0 | E27: =SUMIF('Digital Product Summary by COA'!$C$3:$C$47,$A27,'Digital Product Summary by COA'!$E$3:$E$47) -> 0 | J27: =E27/$E$75 -> 0
A28: Staff Training, Learning & Development Exp | B28: =B86+B143+B200+B257+B314+B371+B428+B485+B542+B599+B656 -> 0 | C28: =C86+C143+C200+C257+C314+C371+C428+C485+C542+C599+C656 -> 0 | D28: =(C28-B28) -> 0 | E28: =SUMIF('Digital Product Summary by COA'!$C$3:$C$47,$A28,'Digital Product Summary by COA'!$E$3:$E$47) -> 0 | J28: =E28/$E$75 -> 0
A29: Recruitment Expenses | B29: =B87+B144+B201+B258+B315+B372+B429+B486+B543+B600+B657 -> 0 | C29: =C87+C144+C201+C258+C315+C372+C429+C486+C543+C600+C657 -> 0 | D29: =(C29-B29) -> 0 | E29: =SUMIF('Digital Product Summary by COA'!$C$3:$C$47,$A29,'Digital Product Summary by COA'!$E$3:$E$47) -> 0 | J29: =E29/$E$75 -> 0
A30: Birthday expenses | B30: =B88+B145+B202+B259+B316+B373+B430+B487+B544+B601+B658 -> 0 | C30: =C88+C145+C202+C259+C316+C373+C430+C487+C544+C601+C658 -> 0 | D30: =(C30-B30) -> 0 | E30: =SUMIF('Digital Product Summary by COA'!$C$3:$C$47,$A30,'Digital Product Summary by COA'!$E$3:$E$47) -> 0 | J30: =E30/$E$75 -> 0
A31: Staff Relocation costs | B31: =B89+B146+B203+B260+B317+B374+B431+B488+B545+B602+B659 -> 0 | C31: =C89+C146+C203+C260+C317+C374+C431+C488+C545+C602+C659 -> 0 | D31: =(C31-B31) -> 0 | E31: =SUMIF('Digital Product Summary by COA'!$C$3:$C$47,$A31,'Digital Product Summary by COA'!$E$3:$E$47) -> 0 | J31: =E31/$E$75 -> 0
A32: ATR Expenses | B32: =B90+B147+B204+B261+B318+B375+B432+B489+B546+B603+B660 -> 0 | C32: =C90+C147+C204+C261+C318+C375+C432+C489+C546+C603+C660 -> 0 | D32: =(C32-B32) -> 0 | E32: =SUMIF('Digital Product Summary by COA'!$C$3:$C$47,$A32,'Digital Product Summary by COA'!$E$3:$E$47) -> 0 | J32: =E32/$E$75 -> 0
A33: Staff Insurance (Employee Medical Insurance) | B33: =B91+B148+B205+B262+B319+B376+B433+B490+B547+B604+B661 -> 0 | C33: =C91+C148+C205+C262+C319+C376+C433+C490+C547+C604+C661 -> 0 | D33: =(C33-B33) -> 0 | E33: =SUMIF('Digital Product Summary by COA'!$C$3:$C$47,$A33,'Digital Product Summary by COA'!$E$3:$E$47) -> 0 | J33: =E33/$E$75 -> 0
A34: Resource Persons | B34: =SUBTOTAL(9,B35) -> 434459 | C34: =SUBTOTAL(9,C35) -> 406523.37 | D34: =(C34-B34)/B34 -> -0.064299799 | E34: =SUBTOTAL(9,E35) -> 439613.03 | F34: =(E34-C34)/C34 -> 0.081396691 | J34: =E34/$E$75 -> 0.20144791
A35: Program Resource Consultant (EHA) | B35: =B93+B150+B207+B264+B321+B378+B435+B492+B549+B606+B663 -> 434459 | C35: =C93+C150+C207+C264+C321+C378+C435+C492+C549+C606+C663 -> 406523.37 | D35: =(C35-B35) -> -27935.626 | E35: =SUMIF('Digital Product Summary by COA'!$C$3:$C$47,$A35,'Digital Product Summary by COA'!$E$3:$E$47) -> 439613.03 | J35: =E35/$E$75 -> 0.20144791
A36: Travel & Lodging Expenses | B36: =SUBTOTAL(9,B37:B42) -> 83637 | C36: =SUBTOTAL(9,C37:C42) -> 54160.169 | D36: =(C36-B36)/B36 -> -0.35243769 | E36: =SUBTOTAL(9,E37:E42) -> 65150.505 | F36: =(E36-C36)/C36 -> 0.20292285 | G36: cut to 2025 levels | J36: =E36/$E$75 -> 0.029854513
A37: Hotel Accomodation | B37: =B95+B152+B209+B266+B323+B380+B437+B494+B551+B608+B665 -> 25883 | C37: =C95+C152+C209+C266+C323+C380+C437+C494+C551+C608+C665 -> 14787.752 | D37: =(C37-B37) -> -11095.248 | E37: =SUMIF('Digital Product Summary by COA'!$C$3:$C$47,$A37,'Digital Product Summary by COA'!$E$3:$E$47) -> 15450.467 | J37: =E37/$E$75 -> 0.0070800092
A38: Food Expenses | B38: =B96+B153+B210+B267+B324+B381+B438+B495+B552+B609+B666 -> 12849 | C38: =C96+C153+C210+C267+C324+C381+C438+C495+C552+C609+C666 -> 7289.9264 | D38: =(C38-B38) -> -5559.0736 | E38: =SUMIF('Digital Product Summary by COA'!$C$3:$C$47,$A38,'Digital Product Summary by COA'!$E$3:$E$47) -> 8600.7328 | J38: =E38/$E$75 -> 0.0039411927
A39: Air fare | B39: =B97+B154+B211+B268+B325+B382+B439+B496+B553+B610+B667 -> 27488 | C39: =C97+C154+C211+C268+C325+C382+C439+C496+C553+C610+C667 -> 25465.248 | D39: =(C39-B39) -> -2022.7524 | E39: =SUMIF('Digital Product Summary by COA'!$C$3:$C$47,$A39,'Digital Product Summary by COA'!$E$3:$E$47) -> 22907.007 | J39: =E39/$E$75 -> 0.010496888
A40: Cab/Auto | B40: =B98+B155+B212+B269+B326+B383+B440+B497+B554+B611+B668 -> 14009 | C40: =C98+C155+C212+C269+C326+C383+C440+C497+C554+C611+C668 -> 3252.0521 | D40: =(C40-B40) -> -10756.948 | E40: =SUMIF('Digital Product Summary by COA'!$C$3:$C$47,$A40,'Digital Product Summary by COA'!$E$3:$E$47) -> 13490.036 | J40: =E40/$E$75 -> 0.0061816629
A41: Bus/Train | B41: =B99+B156+B213+B270+B327+B384+B441+B498+B555+B612+B669 -> 614 | C41: =C99+C156+C213+C270+C327+C384+C441+C498+C555+C612+C669 -> 944.93865 | D41: =(C41-B41) -> 330.93865 | E41: =SUMIF('Digital Product Summary by COA'!$C$3:$C$47,$A41,'Digital Product Summary by COA'!$E$3:$E$47) -> 842.75862 | J41: =E41/$E$75 -> 0.00038618501
A42: Other incidental travel costs | B42: =B100+B157+B214+B271+B328+B385+B442+B499+B556+B613+B670 -> 2794 | C42: =C100+C157+C214+C271+C328+C385+C442+C499+C556+C613+C670 -> 2420.2516 | D42: =(C42-B42) -> -373.74841 | E42: =SUMIF('Digital Product Summary by COA'!$C$3:$C$47,$A42,'Digital Product Summary by COA'!$E$3:$E$47) -> 3859.5036 | J42: =E42/$E$75 -> 0.0017685757
...

Sheet Staff Numbers
A1: 2025 | B1: 2025 | C1: 2025 | E1: Digital Product | F1: 2026 | G1: 2026
B2: FTE | C2: EHA | E2: India, BD, INDO, US | F2: FTE | G2: EHA
A3: Group | D3: Country | E3: Group
D4: India | E4: Country Product
A5: INDIA-Product Management | B5: 23 | C5: 3 | D5: India | E5: Product Management | F5: 23 | G5: 9
A6: INDIA-Platforms-Product Management | D6: India | E6: Country Product | F6: 7 | G6: 10
B7: 1 | C7: 0 | D7: India | E7: Country Engineering | F7: 1 | G7: 0
D8: INDO | E8: Country Product
A9: INDO-Product Management | B9: 2 | C9: 7 | D9: INDO | E9: Country Product | F9: =2+6 -> 8 | G9: =7+5 -> 12
A10: INDO-Tech Ops | B10: 1 | C10: 0 | D10: INDO | E10: Country Engineering | F10: =1+1 -> 2 | G10: 0
D11: BD | E11: Country Product
A12: BD-Product Management | B12: 6 | C12: 22 | D12: BD | E12: Country Product | F12: =6+5 -> 11 | G12: =22-4 -> 18
A13: BD-Tech Ops | B13: 0 | C13: 0 | D13: BD | E13: Country Engineering | F13: =0+1 -> 1 | G13: 0
D14: India | E14: Global Product
A15: INDIA-Platforms-Platforms-Engineering/Software Development | B15: 14 | C15: 2 | D15: India | E15: Global Product | F15: 5 | G15: 1
D16: India | E16: Global Engineering | F16: 14 | G16: 1
D17: Nepal | E17: Country Product
B18: 0 | C18: 0 | D18: Nepal | E18: Country Product | F18: =0+1 -> 1 | G18: =0+3 -> 3
D19: US | E19: Country Product
B20: 0 | C20: 0 | D20: US | E20: Country Product | F20: 0 | G20: 0
A21: Shared Program-Platform | B21: 0 | C21: 1 | D21: US | E21: Country Engineering | F21: 0 | G21: 0
B22: =SUM(B5:B21) -> 47 | C22: =SUM(C5:C21) -> 35 | F22: =SUM(F5:F21) -> 73 | G22: =SUM(G5:G21) -> 54
H25: Increase | I25: Increase
B26: FTE | C26: EHA | F26: FTE | G26: EHA | H26: FTE | I26: EHA
B27: =B5+B6+B7+B15 -> 38 | C27: =C5+C6+C7+C15 -> 5 | E27: India | F27: =F5+F6+F7+F15 -> 36 | G27: =G5+G6+G7+G15 -> 20 | H27: =F27-B27 -> -2 | I27: =G27-C27 -> 15
B28: =B12+B13 -> 6 | C28: =C12+C13 -> 22 | E28: BD | F28: =F12+F13 -> 12 | G28: =G12+G13 -> 18 | H28: =F28-B28 -> 6 | I28: =G28-C28 -> -4
B29: =B9+B10 -> 3 | C29: =C9+C10 -> 7 | E29: INDO | F29: =F9+F10 -> 10 | G29: =G9+G10 -> 12 | H29: =F29-B29 -> 7 | I29: =G29-C29 -> 5
B30: =B18 -> 0 | C30: =C18 -> 0 | E30: Nepal | F30: =F18 -> 1 | G30: =G18 -> 3 | H30: =F30-B30 -> 1 | I30: =G30-C30 -> 3
B31: =B21 -> 0 | C31: =C21 -> 1 | E31: US | F31: =F21 -> 0 | G31: =G21 -> 0 | H31: =F31-B31 -> 0 | I31: =G31-C31 -> -1
B32: =SUM(B27:B31) -> 47 | C32: =SUM(C27:C31) -> 35 | F32: =SUM(F27:F31) -> 59 | G32: =SUM(G27:G31) -> 53 | H32: =F32-B32 -> 12 | I32: =G32-C32 -> 18
B35: FTE | C35: EHA
A44: India | B44: FTE | C44: EHA
A45: Shared Engineering+Product | B45: 15 | C45: 1
A46: India Engineering | B46: 1 | C46: 0
A47: India Product Ops (All MSE's) | B47: 24 | C47: 22
A49: Indonesia
A50: Indo Product | B50: 0 | C50: 9
A51: Indo Product Ops | B51: 0 | C51: 0
A52: Indo Engineering | B52: 1 | C52: 0
A54: Bangladesh
...

Sheet Shared Summary by Dept_US$
C1: Total CY-2026 | D1: 46023 | E1: 46054 | F1: 46082 | G1: 46113 | H1: 46143 | I1: 46174 | J1: 46204 | K1: 46235 | L1: 46266 | M1: 46296 | N1: 46327 | O1: 46357
A2: Country | B2: Group | C2: Budgets | D2: Budgets | E2: Budgets | F2: Budgets | G2: Budgets | H2: Budgets | I2: Budgets | J2: Budgets | K2: Budgets | L2: Budgets | M2: Budgets | N2: Budgets | O2: Budgets
A3: India | B3: Country Product | C3: =SUM(C4:C6) -> 531665.33 | D3: =SUM(D4:D6) -> 43770.841 | E3: =SUM(E4:E6) -> 38870.098 | F3: =SUM(F4:F6) -> 57666.615 | G3: =SUM(G4:G6) -> 56133.971 | H3: =SUM(H4:H6) -> 42531.098 | I3: =SUM(I4:I6) -> 41541.443 | J3: =SUM(J4:J6) -> 42942.592 | ... O3: =SUM(O4:O6) -> 40321.902
A4: India | B4: Product Management (YosAid) | C4: =SUM(D4:O4) -> 289991.06 | D4: =('India- Tech Build Out'!J24+'India- Tech Build Out'!J47+'India- Tech Build Out'!J119)/$B$31 -> 31928.162 | E4: =('India- Tech Build Out'!K24+'India- Tech Build Out'!K47+'India- Tech Build Out'!K119)/$B$31 -> 26228.178 | F4: =('India- Tech Build Out'!L24+'India- Tech Build Out'!L47+'India- Tech Build Out'!L119)/$B$31 -> 41079.484 | G4: =('India- Tech Build Out'!M24+'India- Tech Build Out'!M47+'India- Tech Build Out'!M119)/$B$31 -> 23720.407 | H4: =('India- Tech Build Out'!N24+'India- Tech Build Out'!N47+'India- Tech Build Out'!N119)/$B$31 -> 20735.925 | I4: =('India- Tech Build Out'!O24+'India- Tech Build Out'!O47+'India- Tech Build Out'!O119)/$B$31 -> 20643.97 | J4: =('India- Tech Build Out'!P24+'India- Tech Build Out'!P47+'India- Tech Build Out'!P119)/$B$31 -> 20643.97 | K4: =('India- Tech Build Out'!Q24+'India- Tech Build Out'!Q47+'India- Tech Build Out'!Q119)/$B$31 -> 21392.246 | ... O4: =('India- Tech Build Out'!U24+'India- Tech Build Out'!U47+'India- Tech Build Out'!U119)/$B$31 -> 20643.97
A5: India | B5: Country Product | C5: =SUM(D5:O5) -> 223283.46 | D5: ='India- Tech Build Out'!J70/$B$31 -> 10310.112 | E5: ='India- Tech Build Out'!K70/$B$31 -> 11109.353 | F5: ='India- Tech Build Out'!L70/$B$31 -> 15054.564 | G5: ='India- Tech Build Out'!M70/$B$31 -> 30880.997 | H5: ='India- Tech Build Out'!N70/$B$31 -> 20262.606 | I5: ='India- Tech Build Out'!O70/$B$31 -> 19364.905 | J5: ='India- Tech Build Out'!P70/$B$31 -> 20766.055 | K5: ='India- Tech Build Out'!Q70/$B$31 -> 19113.181 | ... O5: ='India- Tech Build Out'!U70/$B$31 -> 18145.365
A6: India | B6: Country Engineering | C6: =SUM(D6:O6) -> 18390.805 | D6: ='India- Tech Build Out'!J92/$B$31 -> 1532.567 | E6: ='India- Tech Build Out'!K92/$B$31 -> 1532.567 | F6: ='India- Tech Build Out'!L92/$B$31 -> 1532.567 | G6: ='India- Tech Build Out'!M92/$B$31 -> 1532.567 | H6: ='India- Tech Build Out'!N92/$B$31 -> 1532.567 | I6: ='India- Tech Build Out'!O92/$B$31 -> 1532.567 | J6: ='India- Tech Build Out'!P92/$B$31 -> 1532.567 | K6: ='India- Tech Build Out'!Q92/$B$31 -> 1532.567 | ... O6: ='India- Tech Build Out'!U92/$B$31 -> 1532.567
A7: INDO | B7: Country Product | C7: =SUM(C8:C9) -> 242826.62 | D7: =SUM(D8:D9) -> 9458.1778 | E7: =SUM(E8:E9) -> 12795.886 | F7: =SUM(F8:F9) -> 14350.067 | G7: =SUM(G8:G9) -> 29523.507 | H7: =SUM(H8:H9) -> 18447.401 | I7: =SUM(I8:I9) -> 20644.086 | J7: =SUM(J8:J9) -> 21373.295 | ... O7: =SUM(O8:O9) -> 23369.213
A8: INDO | B8: Country Product | C8: =SUM(D8:O8) -> 196165.93 | D8: ='INDO- Tech Build-Out'!J23/$B$32 -> 7422.5314 | E8: ='INDO- Tech Build-Out'!K23/$B$32 -> 9650.0829 | F8: ='INDO- Tech Build-Out'!L23/$B$32 -> 7808.1704 | G8: ='INDO- Tech Build-Out'!M23/$B$32 -> 21539.475 | H8: ='INDO- Tech Build-Out'!N23/$B$32 -> 15113.369 | I8: ='INDO- Tech Build-Out'!O23/$B$32 -> 17310.054 | J8: ='INDO- Tech Build-Out'!P23/$B$32 -> 18039.263 | K8: ='INDO- Tech Build-Out'!Q23/$B$32 -> 17994.429 | ... O8: ='INDO- Tech Build-Out'!U23/$B$32 -> 20035.181
A9: INDO | B9: Engineering | C9: =SUM(D9:O9) -> 46660.691 | D9: ='INDO- Tech Build-Out'!J46/$B$32 -> 2035.6464 | E9: ='INDO- Tech Build-Out'!K46/$B$32 -> 3145.8027 | F9: ='INDO- Tech Build-Out'!L46/$B$32 -> 6541.8964 | G9: ='INDO- Tech Build-Out'!M46/$B$32 -> 7984.0314 | H9: ='INDO- Tech Build-Out'!N46/$B$32 -> 3334.0314 | I9: ='INDO- Tech Build-Out'!O46/$B$32 -> 3334.0314 | J9: ='INDO- Tech Build-Out'!P46/$B$32 -> 3334.0314 | K9: ='INDO- Tech Build-Out'!Q46/$B$32 -> 3334.0314 | ... O9: ='INDO- Tech Build-Out'!U46/$B$32 -> 3334.0314
A10: BD | B10: Country Product | C10: =SUM(C11:C12) -> 200751.23 | D10: =SUM(D11:D12) -> 10962.56 | E10: =SUM(E11:E12) -> 27383.84 | F10: =SUM(F11:F12) -> 16089.138 | G10: =SUM(G11:G12) -> 15430.804 | H10: =SUM(H11:H12) -> 19475.507 | I10: =SUM(I11:I12) -> 16001.638 | J10: =SUM(J11:J12) -> 17316.221 | ... O10: =SUM(O11:O12) -> 15026.638
A11: BD | B11: Country Product | C11: =SUM(D11:O11) -> 185576.23 | D11: ='BD- Tech Build-Out'!J23/$B$33 -> 10962.56 | E11: ='BD- Tech Build-Out'!K23/$B$33 -> 25300.507 | F11: ='BD- Tech Build-Out'!L23/$B$33 -> 14826.638 | G11: ='BD- Tech Build-Out'!M23/$B$33 -> 13934.971 | H11: ='BD- Tech Build-Out'!N23/$B$33 -> 18213.007 | I11: ='BD- Tech Build-Out'!O23/$B$33 -> 14739.138 | J11: ='BD- Tech Build-Out'!P23/$B$33 -> 16053.721 | K11: ='BD- Tech Build-Out'!Q23/$B$33 -> 14539.138 | ... O11: ='BD- Tech Build-Out'!U23/$B$33 -> 13764.138
A12: BD | B12: Engineering | C12: =SUM(D12:O12) -> 15175 | D12: ='BD- Tech Build-Out'!J46/$B$33 -> 0 | E12: ='BD- Tech Build-Out'!K46/$B$33 -> 2083.3333 | F12: ='BD- Tech Build-Out'!L46/$B$33 -> 1262.5 | G12: ='BD- Tech Build-Out'!M46/$B$33 -> 1495.8333 | H12: ='BD- Tech Build-Out'!N46/$B$33 -> 1262.5 | I12: ='BD- Tech Build-Out'!O46/$B$33 -> 1262.5 | J12: ='BD- Tech Build-Out'!P46/$B$33 -> 1262.5 | K12: ='BD- Tech Build-Out'!Q46/$B$33 -> 1495.8333 | ... O12: ='BD- Tech Build-Out'!U46/$B$33 -> 1262.5
A13: India | B13: Global Product | C13: =SUM(C14:C15) -> 896975.54 | D13: =SUM(D14:D15) -> 57857.212 | E13: =SUM(E14:E15) -> 57857.212 | F13: =SUM(F14:F15) -> 77009.702 | G13: =SUM(G14:G15) -> 77578.668 | H13: =SUM(H14:H15) -> 86056.062 | I13: =SUM(I14:I15) -> 84623.412 | J13: =SUM(J14:J15) -> 75497.154 | ... O13: =SUM(O14:O15) -> 75497.154
A14: India | B14: Global Product | C14: =SUM(D14:O14) -> 326653.49 | D14: ='India- Tech Build Out'!J115/$B$31 -> 27028.395 | E14: ='India- Tech Build Out'!K115/$B$31 -> 27028.395 | F14: ='India- Tech Build Out'!L115/$B$31 -> 30184.716 | G14: ='India- Tech Build Out'!M115/$B$31 -> 31131.843 | H14: ='India- Tech Build Out'!N115/$B$31 -> 34053.682 | I14: ='India- Tech Build Out'!O115/$B$31 -> 31438.273 | J14: ='India- Tech Build Out'!P115/$B$31 -> 23978.682 | K14: ='India- Tech Build Out'!Q115/$B$31 -> 23978.682 | ... O14: ='India- Tech Build Out'!U115/$B$31 -> 23978.682
A15: India | B15: Global Engineering | C15: =SUM(D15:O15) -> 570322.05 | D15: ='India- Tech Build Out'!J142/$B$31 -> 30828.817 | E15: ='India- Tech Build Out'!K142/$B$31 -> 30828.817 | F15: ='India- Tech Build Out'!L142/$B$31 -> 46824.986 | G15: ='India- Tech Build Out'!M142/$B$31 -> 46446.825 | H15: ='India- Tech Build Out'!N142/$B$31 -> 52002.38 | I15: ='India- Tech Build Out'!O142/$B$31 -> 53185.139 | J15: ='India- Tech Build Out'!P142/$B$31 -> 51518.472 | K15: ='India- Tech Build Out'!Q142/$B$31 -> 52612.725 | ... O15: ='India- Tech Build Out'!U142/$B$31 -> 51518.472
A16: Nepal | B16: Country Product | C16: =SUM(C17) -> 21193.778 | D16: =SUM(D17) -> 1025.4074 | E16: =SUM(E17) -> 1025.4074 | F16: =SUM(F17) -> 1580.963 | G16: =SUM(G17) -> 1580.963 | H16: =SUM(H17) -> 1580.963 | I16: =SUM(I17) -> 1580.963 | J16: =SUM(J17) -> 2136.5185 | ... O16: =SUM(O17) -> 2136.5185
A17: Nepal | B17: Engineering | C17: =SUM(D17:O17) -> 21193.778 | D17: ='Nepal- Tech Build Out'!J23/$B$34 -> 1025.4074 | E17: ='Nepal- Tech Build Out'!K23/$B$34 -> 1025.4074 | F17: ='Nepal- Tech Build Out'!L23/$B$34 -> 1580.963 | G17: ='Nepal- Tech Build Out'!M23/$B$34 -> 1580.963 | H17: ='Nepal- Tech Build Out'!N23/$B$34 -> 1580.963 | I17: ='Nepal- Tech Build Out'!O23/$B$34 -> 1580.963 | J17: ='Nepal- Tech Build Out'!P23/$B$34 -> 2136.5185 | K17: ='Nepal- Tech Build Out'!Q23/$B$34 -> 2136.5185 | ... O17: ='Nepal- Tech Build Out'!U23/$B$34 -> 2136.5185
A18: US | B18: Country Product | C18: =SUM(C19:C20) -> 288854 | D18: =SUM(D19:D20) -> 37152.667 | E18: =SUM(E19:E20) -> 24685.667 | F18: =SUM(F19:F20) -> 25525.667 | G18: =SUM(G19:G20) -> 22182.667 | H18: =SUM(H19:H20) -> 22758.667 | I18: =SUM(I19:I20) -> 21745.667 | J18: =SUM(J19:J20) -> 24333.667 | ... O18: =SUM(O19:O20) -> 21770.667
A19: US | B19: Country Product | C19: =SUM(D19:O19) -> 0 | D19: ='US- Tech Build Out'!J23 -> 0 | E19: ='US- Tech Build Out'!K23 -> 0 | F19: ='US- Tech Build Out'!L23 -> 0 | G19: ='US- Tech Build Out'!M23 -> 0 | H19: ='US- Tech Build Out'!N23 -> 0 | I19: ='US- Tech Build Out'!O23 -> 0 | J19: ='US- Tech Build Out'!P23 -> 0 | K19: ='US- Tech Build Out'!Q23 -> 0 | ... O19: ='US- Tech Build Out'!U23 -> 0
A20: US | B20: Engineering | C20: =SUM(D20:O20) -> 288854 | D20: ='US- Tech Build Out'!J46 -> 37152.667 | E20: ='US- Tech Build Out'!K46 -> 24685.667 | F20: ='US- Tech Build Out'!L46 -> 25525.667 | G20: ='US- Tech Build Out'!M46 -> 22182.667 | H20: ='US- Tech Build Out'!N46 -> 22758.667 | I20: ='US- Tech Build Out'!O46 -> 21745.667 | J20: ='US- Tech Build Out'!P46 -> 24333.667 | K20: ='US- Tech Build Out'!Q46 -> 21855.667 | ... O20: ='US- Tech Build Out'!U46 -> 21770.667
C21: =C3+C7+C10+C13+C16+C18 -> 2182266.5 | D21: =D3+D7+D10+D13+D16+D18 -> 160226.86 | E21: =E3+E7+E10+E13+E16+E18 -> 162618.11 | F21: =F3+F7+F10+F13+F16+F18 -> 192222.15 | G21: =G3+G7+G10+G13+G16+G18 -> 202430.58 | H21: =H3+H7+H10+H13+H16+H18 -> 190849.7 | I21: =I3+I7+I10+I13+I16+I18 -> 186137.21 | J21: =J3+J7+J10+J13+J16+J18 -> 183599.45 | ... O21: =O3+O7+O10+O13+O16+O18 -> 178122.09
B22: Check | C22: =C21-'Digital Product Summary by COA'!E49 -> 0 | D22: =D21-'Digital Product Summary by COA'!F49 -> 0 | E22: =E21-'Digital Product Summary by COA'!G49 -> 0 | F22: =F21-'Digital Product Summary by COA'!H49 -> 0 | G22: =G21-'Digital Product Summary by COA'!I49 -> 0 | H22: =H21-'Digital Product Summary by COA'!J49 -> 0 | I22: =I21-'Digital Product Summary by COA'!K49 -> 0 | J22: =J21-'Digital Product Summary by COA'!L49 -> 0 | ... O22: =O21-'Digital Product Summary by COA'!Q49 -> 0
A31: INR | B31: 87
A32: IDR | B32: 16000
A33: BDT | B33: 120
A34: NPR | B34: 135
A35: US | B35: 1

Sheet Digital Product Summary by COA
A1: Country | B1: Parent account | C1: GL Description | D1: Ledger Code | E1: Total CY-2026 | F1: 46023 | G1: 46054 | H1: 46082 | I1: 46113 | J1: 46143 | K1: 46174 | L1: 46204 | M1: 46235 | N1: 46266 | O1: 46296 | P1: 46327 | Q1: 46357
E2: Budgets | F2: Budgets | G2: Budgets | H2: Budgets | I2: Budgets | J2: Budgets | K2: Budgets | L2: Budgets | M2: Budgets | N2: Budgets | O2: Budgets | P2: Budgets | Q2: Budgets
A3: Digital product | B3: Salaries and Wages | C3: Salaries and Wages | D3: 91101-91107 | E3: =SUM(F3:Q3) -> 1229549.1 | F3: =SUMIFS(F$53:F$318,$A$53:$A$318,"India",$C$53:$C$318,$C3)/'Shared Summary by Dept_US$'!$B$31+SUMIFS(F$53:F$318,$A$53:$A$318,"INDO",$C$53:$C$318,$C3)/'Shared Summary by Dept_US$'!$B$32+SUMIFS(F$53:F$318,$A$53:$A$318,"BD",$C$53:$C$318,$C3)/'Shared Summary by Dept_US$'!$B$33+SUMIFS(F$53:F$318,$A$53:$A$318,"Nepal",$C$53:$C$318,$C3)/'Shared Summary by Dept_US$'!$B$34+SUMIFS(F$53:F$318,$A$53:$A$318,"US",$C$53:$C$318,$C3)/'Shared Summary by Dept_US$'!$B$35 -> 76195.929 | G3: =SUMIFS(G$53:G$318,$A$53:$A$318,"India",$C$53:$C$318,$C3)/'Shared Summary by Dept_US$'!$B$31+SUMIFS(G$53:G$318,$A$53:$A$318,"INDO",$C$53:$C$318,$C3)/'Shared Summary by Dept_US$'!$B$32+SUMIFS(G$53:G$318,$A$53:$A$318,"BD",$C$53:$C$318,$C3)/'Shared Summary by Dept_US$'!$B$33+SUMIFS(G$53:G$318,$A$53:$A$318,"Nepal",$C$53:$C$318,$C3)/'Shared Summary by Dept_US$'!$B$34+SUMIFS(G$53:G$318,$A$53:$A$318,"US",$C$53:$C$318,$C3)/'Shared Summary by Dept_US$'!$B$35 -> 80973.188 | H3: =SUMIFS(H$53:H$318,$A$53:$A$318,"India",$C$53:$C$318,$C3)/'Shared Summary by Dept_US$'!$B$31+SUMIFS(H$53:H$318,$A$53:$A$318,"INDO",$C$53:$C$318,$C3)/'Shared Summary by Dept_US$'!$B$32+SUMIFS(H$53:H$318,$A$53:$A$318,"BD",$C$53:$C$318,$C3)/'Shared Summary by Dept_US$'!$B$33+SUMIFS(H$53:H$318,$A$53:$A$318,"Nepal",$C$53:$C$318,$C3)/'Shared Summary by Dept_US$'!$B$34+SUMIFS(H$53:H$318,$A$53:$A$318,"US",$C$53:$C$318,$C3)/'Shared Summary by Dept_US$'!$B$35 -> 81308.244 | I3: =SUMIFS(I$53:I$318,$A$53:$A$318,"India",$C$53:$C$318,$C3)/'Shared Summary by Dept_US$'!$B$31+SUMIFS(I$53:I$318,$A$53:$A$318,"INDO",$C$53:$C$318,$C3)/'Shared Summary by Dept_US$'!$B$32+SUMIFS(I$53:I$318,$A$53:$A$318,"BD",$C$53:$C$318,$C3)/'Shared Summary by Dept_US$'!$B$33+SUMIFS(I$53:I$318,$A$53:$A$318,"Nepal",$C$53:$C$318,$C3)/'Shared Summary by Dept_US$'!$B$34+SUMIFS(I$53:I$318,$A$53:$A$318,"US",$C$53:$C$318,$C3)/'Shared Summary by Dept_US$'!$B$35 -> 104534.12 | J3: =SUMIFS(J$53:J$318,$A$53:$A$318,"India",$C$53:$C$318,$C3)/'Shared Summary by Dept_US$'!$B$31+SUMIFS(J$53:J$318,$A$53:$A$318,"INDO",$C$53:$C$318,$C3)/'Shared Summary by Dept_US$'!$B$32+SUMIFS(J$53:J$318,$A$53:$A$318,"BD",$C$53:$C$318,$C3)/'Shared Summary by Dept_US$'!$B$33+SUMIFS(J$53:J$318,$A$53:$A$318,"Nepal",$C$53:$C$318,$C3)/'Shared Summary by Dept_US$'!$B$34+SUMIFS(J$53:J$318,$A$53:$A$318,"US",$C$53:$C$318,$C3)/'Shared Summary by Dept_US$'!$B$35 -> 112902.96 | K3: =SUMIFS(K$53:K$318,$A$53:$A$318,"India",$C$53:$C$318,$C3)/'Shared Summary by Dept_US$'!$B$31+SUMIFS(K$53:K$318,$A$53:$A$318,"INDO",$C$53:$C$318,$C3)/'Shared Summary by Dept_US$'!$B$32+SUMIFS(K$53:K$318,$A$53:$A$318,"BD",$C$53:$C$318,$C3)/'Shared Summary by Dept_US$'!$B$33+SUMIFS(K$53:K$318,$A$53:$A$318,"Nepal",$C$53:$C$318,$C3)/'Shared Summary by Dept_US$'!$B$34+SUMIFS(K$53:K$318,$A$53:$A$318,"US",$C$53:$C$318,$C3)/'Shared Summary by Dept_US$'!$B$35 -> 112657.08 | L3: =SUMIFS(L$53:L$318,$A$53:$A$318,"India",$C$53:$C$318,$C3)/'Shared Summary by Dept_US$'!$B$31+SUMIFS(L$53:L$318,$A$53:$A$318,"INDO",$C$53:$C$318,$C3)/'Shared Summary by Dept_US$'!$B$32+SUMIFS(L$53:L$318,$A$53:$A$318,"BD",$C$53:$C$318,$C3)/'Shared Summary by Dept_US$'!$B$33+SUMIFS(L$53:L$318,$A$53:$A$318,"Nepal",$C$53:$C$318,$C3)/'Shared Summary by Dept_US$'!$B$34+SUMIFS(L$53:L$318,$A$53:$A$318,"US",$C$53:$C$318,$C3)/'Shared Summary by Dept_US$'!$B$35 -> 110162.93 | M3: =SUMIFS(M$53:M$318,$A$53:$A$318,"India",$C$53:$C$318,$C3)/'Shared Summary by Dept_US$'!$B$31+SUMIFS(M$53:M$318,$A$53:$A$318,"INDO",$C$53:$C$318,$C3)/'Shared Summary by Dept_US$'!$B$32+SUMIFS(M$53:M$318,$A$53:$A$318,"BD",$C$53:$C$318,$C3)/'Shared Summary by Dept_US$'!$B$33+SUMIFS(M$53:M$318,$A$53:$A$318,"Nepal",$C$53:$C$318,$C3)/'Shared Summary by Dept_US$'!$B$34+SUMIFS(M$53:M$318,$A$53:$A$318,"US",$C$53:$C$318,$C3)/'Shared Summary by Dept_US$'!$B$35 -> 110162.93 | ... Q3: =SUMIFS(Q$53:Q$318,$A$53:$A$318,"India",$C$53:$C$318,$C3)/'Shared Summary by Dept_US$'!$B$31+SUMIFS(Q$53:Q$318,$A$53:$A$318,"INDO",$C$53:$C$318,$C3)/'Shared Summary by Dept_US$'!$B$32+SUMIFS(Q$53:Q$318,$A$53:$A$318,"BD",$C$53:$C$318,$C3)/'Shared Summary by Dept_US$'!$B$33+SUMIFS(Q$53:Q$318,$A$53:$A$318,"Nepal",$C$53:$C$318,$C3)/'Shared Summary by Dept_US$'!$B$34+SUMIFS(Q$53:Q$318,$A$53:$A$318,"US",$C$53:$C$318,$C3)/'Shared Summary by Dept_US$'!$B$35 -> 110162.93
A4: Digital product | B4: Health and Retirement Benefits | C4: Gratuity & Bonus | D4: 91201-91207 | E4: =SUM(F4:Q4) -> 21501.757 | F4: =SUMIFS(F$53:F$318,$A$53:$A$318,"India",$C$53:$C$318,$C4)/'Shared Summary by Dept_US$'!$B$31+SUMIFS(F$53:F$318,$A$53:$A$318,"INDO",$C$53:$C$318,$C4)/'Shared Summary by Dept_US$'!$B$32+SUMIFS(F$53:F$318,$A$53:$A$318,"BD",$C$53:$C$318,$C4)/'Shared Summary by Dept_US$'!$B$33+SUMIFS(F$53:F$318,$A$53:$A$318,"Nepal",$C$53:$C$318,$C4)/'Shared Summary by Dept_US$'!$B$34+SUMIFS(F$53:F$318,$A$53:$A$318,"US",$C$53:$C$318,$C4)/'Shared Summary by Dept_US$'!$B$35 -> 1491.1494 | G4: =SUMIFS(G$53:G$318,$A$53:$A$318,"India",$C$53:$C$318,$C4)/'Shared Summary by Dept_US$'!$B$31+SUMIFS(G$53:G$318,$A$53:$A$318,"INDO",$C$53:$C$318,$C4)/'Shared Summary by Dept_US$'!$B$32+SUMIFS(G$53:G$318,$A$53:$A$318,"BD",$C$53:$C$318,$C4)/'Shared Summary by Dept_US$'!$B$33+SUMIFS(G$53:G$318,$A$53:$A$318,"Nepal",$C$53:$C$318,$C4)/'Shared Summary by Dept_US$'!$B$34+SUMIFS(G$53:G$318,$A$53:$A$318,"US",$C$53:$C$318,$C4)/'Shared Summary by Dept_US$'!$B$35 -> 837.2 | H4: =SUMIFS(H$53:H$318,$A$53:$A$318,"India",$C$53:$C$318,$C4)/'Shared Summary by Dept_US$'!$B$31+SUMIFS(H$53:H$318,$A$53:$A$318,"INDO",$C$53:$C$318,$C4)/'Shared Summary by Dept_US$'!$B$32+SUMIFS(H$53:H$318,$A$53:$A$318,"BD",$C$53:$C$318,$C4)/'Shared Summary by Dept_US$'!$B$33+SUMIFS(H$53:H$318,$A$53:$A$318,"Nepal",$C$53:$C$318,$C4)/'Shared Summary by Dept_US$'!$B$34+SUMIFS(H$53:H$318,$A$53:$A$318,"US",$C$53:$C$318,$C4)/'Shared Summary by Dept_US$'!$B$35 -> 15204.598 | I4: =SUMIFS(I$53:I$318,$A$53:$A$318,"India",$C$53:$C$318,$C4)/'Shared Summary by Dept_US$'!$B$31+SUMIFS(I$53:I$318,$A$53:$A$318,"INDO",$C$53:$C$318,$C4)/'Shared Summary by Dept_US$'!$B$32+SUMIFS(I$53:I$318,$A$53:$A$318,"BD",$C$53:$C$318,$C4)/'Shared Summary by Dept_US$'!$B$33+SUMIFS(I$53:I$318,$A$53:$A$318,"Nepal",$C$53:$C$318,$C4)/'Shared Summary by Dept_US$'!$B$34+SUMIFS(I$53:I$318,$A$53:$A$318,"US",$C$53:$C$318,$C4)/'Shared Summary by Dept_US$'!$B$35 -> 0 | J4: =SUMIFS(J$53:J$318,$A$53:$A$318,"India",$C$53:$C$318,$C4)/'Shared Summary by Dept_US$'!$B$31+SUMIFS(J$53:J$318,$A$53:$A$318,"INDO",$C$53:$C$318,$C4)/'Shared Summary by Dept_US$'!$B$32+SUMIFS(J$53:J$318,$A$53:$A$318,"BD",$C$53:$C$318,$C4)/'Shared Summary by Dept_US$'!$B$33+SUMIFS(J$53:J$318,$A$53:$A$318,"Nepal",$C$53:$C$318,$C4)/'Shared Summary by Dept_US$'!$B$34+SUMIFS(J$53:J$318,$A$53:$A$318,"US",$C$53:$C$318,$C4)/'Shared Summary by Dept_US$'!$B$35 -> 0 | K4: =SUMIFS(K$53:K$318,$A$53:$A$318,"India",$C$53:$C$318,$C4)/'Shared Summary by Dept_US$'!$B$31+SUMIFS(K$53:K$318,$A$53:$A$318,"INDO",$C$53:$C$318,$C4)/'Shared Summary by Dept_US$'!$B$32+SUMIFS(K$53:K$318,$A$53:$A$318,"BD",$C$53:$C$318,$C4)/'Shared Summary by Dept_US$'!$B$33+SUMIFS(K$53:K$318,$A$53:$A$318,"Nepal",$C$53:$C$318,$C4)/'Shared Summary by Dept_US$'!$B$34+SUMIFS(K$53:K$318,$A$53:$A$318,"US",$C$53:$C$318,$C4)/'Shared Summary by Dept_US$'!$B$35 -> 3190.3381 | L4: =SUMIFS(L$53:L$318,$A$53:$A$318,"India",$C$53:$C$318,$C4)/'Shared Summary by Dept_US$'!$B$31+SUMIFS(L$53:L$318,$A$53:$A$318,"INDO",$C$53:$C$318,$C4)/'Shared Summary by Dept_US$'!$B$32+SUMIFS(L$53:L$318,$A$53:$A$318,"BD",$C$53:$C$318,$C4)/'Shared Summary by Dept_US$'!$B$33+SUMIFS(L$53:L$318,$A$53:$A$318,"Nepal",$C$53:$C$318,$C4)/'Shared Summary by Dept_US$'!$B$34+SUMIFS(L$53:L$318,$A$53:$A$318,"US",$C$53:$C$318,$C4)/'Shared Summary by Dept_US$'!$B$35 -> 0 | M4: =SUMIFS(M$53:M$318,$A$53:$A$318,"India",$C$53:$C$318,$C4)/'Shared Summary by Dept_US$'!$B$31+SUMIFS(M$53:M$318,$A$53:$A$318,"INDO",$C$53:$C$318,$C4)/'Shared Summary by Dept_US$'!$B$32+SUMIFS(M$53:M$318,$A$53:$A$318,"BD",$C$53:$C$318,$C4)/'Shared Summary by Dept_US$'!$B$33+SUMIFS(M$53:M$318,$A$53:$A$318,"Nepal",$C$53:$C$318,$C4)/'Shared Summary by Dept_US$'!$B$34+SUMIFS(M$53:M$318,$A$53:$A$318,"US",$C$53:$C$318,$C4)/'Shared Summary by Dept_US$'!$B$35 -> 0 | ... Q4: =SUMIFS(Q$53:Q$318,$A$53:$A$318,"India",$C$53:$C$318,$C4)/'Shared Summary by Dept_US$'!$B$31+SUMIFS(Q$53:Q$318,$A$53:$A$318,"INDO",$C$53:$C$318,$C4)/'Shared Summary by Dept_US$'!$B$32+SUMIFS(Q$53:Q$318,$A$53:$A$318,"BD",$C$53:$C$318,$C4)/'Shared Summary by Dept_US$'!$B$33+SUMIFS(Q$53:Q$318,$A$53:$A$318,"Nepal",$C$53:$C$318,$C4)/'Shared Summary by Dept_US$'!$B$34+SUMIFS(Q$53:Q$318,$A$53:$A$318,"US",$C$53:$C$318,$C4)/'Shared Summary by Dept_US$'!$B$35 -> 0
A5: Digital product | B5: Health and Retirement Benefits | C5: Staff Insurance | D5: 91207 | E5: =SUM(F5:Q5) -> 0 | F5: =SUMIFS(F$53:F$318,$A$53:$A$318,"India",$C$53:$C$318,$C5)/'Shared Summary by Dept_US$'!$B$31+SUMIFS(F$53:F$318,$A$53:$A$318,"INDO",$C$53:$C$318,$C5)/'Shared Summary by Dept_US$'!$B$32+SUMIFS(F$53:F$318,$A$53:$A$318,"BD",$C$53:$C$318,$C5)/'Shared Summary by Dept_US$'!$B$33+SUMIFS(F$53:F$318,$A$53:$A$318,"Nepal",$C$53:$C$318,$C5)/'Shared Summary by Dept_US$'!$B$34+SUMIFS(F$53:F$318,$A$53:$A$318,"US",$C$53:$C$318,$C5)/'Shared Summary by Dept_US$'!$B$35 -> 0 | G5: =SUMIFS(G$53:G$318,$A$53:$A$318,"India",$C$53:$C$318,$C5)/'Shared Summary by Dept_US$'!$B$31+SUMIFS(G$53:G$318,$A$53:$A$318,"INDO",$C$53:$C$318,$C5)/'Shared Summary by Dept_US$'!$B$32+SUMIFS(G$53:G$318,$A$53:$A$318,"BD",$C$53:$C$318,$C5)/'Shared Summary by Dept_US$'!$B$33+SUMIFS(G$53:G$318,$A$53:$A$318,"Nepal",$C$53:$C$318,$C5)/'Shared Summary by Dept_US$'!$B$34+SUMIFS(G$53:G$318,$A$53:$A$318,"US",$C$53:$C$318,$C5)/'Shared Summary by Dept_US$'!$B$35 -> 0 | H5: =SUMIFS(H$53:H$318,$A$53:$A$318,"India",$C$53:$C$318,$C5)/'Shared Summary by Dept_US$'!$B$31+SUMIFS(H$53:H$318,$A$53:$A$318,"INDO",$C$53:$C$318,$C5)/'Shared Summary by Dept_US$'!$B$32+SUMIFS(H$53:H$318,$A$53:$A$318,"BD",$C$53:$C$318,$C5)/'Shared Summary by Dept_US$'!$B$33+SUMIFS(H$53:H$318,$A$53:$A$318,"Nepal",$C$53:$C$318,$C5)/'Shared Summary by Dept_US$'!$B$34+SUMIFS(H$53:H$318,$A$53:$A$318,"US",$C$53:$C$318,$C5)/'Shared Summary by Dept_US$'!$B$35 -> 0 | I5: =SUMIFS(I$53:I$318,$A$53:$A$318,"India",$C$53:$C$318,$C5)/'Shared Summary by Dept_US$'!$B$31+SUMIFS(I$53:I$318,$A$53:$A$318,"INDO",$C$53:$C$318,$C5)/'Shared Summary by Dept_US$'!$B$32+SUMIFS(I$53:I$318,$A$53:$A$318,"BD",$C$53:$C$318,$C5)/'Shared Summary by Dept_US$'!$B$33+SUMIFS(I$53:I$318,$A$53:$A$318,"Nepal",$C$53:$C$318,$C5)/'Shared Summary by Dept_US$'!$B$34+SUMIFS(I$53:I$318,$A$53:$A$318,"US",$C$53:$C$318,$C5)/'Shared Summary by Dept_US$'!$B$35 -> 0 | J5: =SUMIFS(J$53:J$318,$A$53:$A$318,"India",$C$53:$C$318,$C5)/'Shared Summary by Dept_US$'!$B$31+SUMIFS(J$53:J$318,$A$53:$A$318,"INDO",$C$53:$C$318,$C5)/'Shared Summary by Dept_US$'!$B$32+SUMIFS(J$53:J$318,$A$53:$A$318,"BD",$C$53:$C$318,$C5)/'Shared Summary by Dept_US$'!$B$33+SUMIFS(J$53:J$318,$A$53:$A$318,"Nepal",$C$53:$C$318,$C5)/'Shared Summary by Dept_US$'!$B$34+SUMIFS(J$53:J$318,$A$53:$A$318,"US",$C$53:$C$318,$C5)/'Shared Summary by Dept_US$'!$B$35 -> 0 | K5: =SUMIFS(K$53:K$318,$A$53:$A$318,"India",$C$53:$C$318,$C5)/'Shared Summary by Dept_US$'!$B$31+SUMIFS(K$53:K$318,$A$53:$A$318,"INDO",$C$53:$C$318,$C5)/'Shared Summary by Dept_US$'!$B$32+SUMIFS(K$53:K$318,$A$53:$A$318,"BD",$C$53:$C$318,$C5)/'Shared Summary by Dept_US$'!$B$33+SUMIFS(K$53:K$318,$A$53:$A$318,"Nepal",$C$53:$C$318,$C5)/'Shared Summary by Dept_US$'!$B$34+SUMIFS(K$53:K$318,$A$53:$A$318,"US",$C$53:$C$318,$C5)/'Shared Summary by Dept_US$'!$B$35 -> 0 | L5: =SUMIFS(L$53:L$318,$A$53:$A$318,"India",$C$53:$C$318,$C5)/'Shared Summary by Dept_US$'!$B$31+SUMIFS(L$53:L$318,$A$53:$A$318,"INDO",$C$53:$C$318,$C5)/'Shared Summary by Dept_US$'!$B$32+SUMIFS(L$53:L$318,$A$53:$A$318,"BD",$C$53:$C$318,$C5)/'Shared Summary by Dept_US$'!$B$33+SUMIFS(L$53:L$318,$A$53:$A$318,"Nepal",$C$53:$C$318,$C5)/'Shared Summary by Dept_US$'!$B$34+SUMIFS(L$53:L$318,$A$53:$A$318,"US",$C$53:$C$318,$C5)/'Shared Summary by Dept_US$'!$B$35 -> 0 | M5: =SUMIFS(M$53:M$318,$A$53:$A$318,"India",$C$53:$C$318,$C5)/'Shared Summary by Dept_US$'!$B$31+SUMIFS(M$53:M$318,$A$53:$A$318,"INDO",$C$53:$C$318,$C5)/'Shared Summary by Dept_US$'!$B$32+SUMIFS(M$53:M$318,$A$53:$A$318,"BD",$C$53:$C$318,$C5)/'Shared Summary by Dept_US$'!$B$33+SUMIFS(M$53:M$318,$A$53:$A$318,"Nepal",$C$53:$C$318,$C5)/'Shared Summary by Dept_US$'!$B$34+SUMIFS(M$53:M$318,$A$53:$A$318,"US",$C$53:$C$318,$C5)/'Shared Summary by Dept_US$'!$B$35 -> 0 | ... Q5: =SUMIFS(Q$53:Q$318,$A$53:$A$318,"India",$C$53:$C$318,$C5)/'Shared Summary by Dept_US$'!$B$31+SUMIFS(Q$53:Q$318,$A$53:$A$318,"INDO",$C$53:$C$318,$C5)/'Shared Summary by Dept_US$'!$B$32+SUMIFS(Q$53:Q$318,$A$53:$A$318,"BD",$C$53:$C$318,$C5)/'Shared Summary by Dept_US$'!$B$33+SUMIFS(Q$53:Q$318,$A$53:$A$318,"Nepal",$C$53:$C$318,$C5)/'Shared Summary by Dept_US$'!$B$34+SUMIFS(Q$53:Q$318,$A$53:$A$318,"US",$C$53:$C$318,$C5)/'Shared Summary by Dept_US$'!$B$35 -> 0
A6: Digital product | B6: Other Staff Expenses | C6: Internal meetings | D6: 91301 | E6: =SUM(F6:Q6) -> 0 | F6: =SUMIFS(F$53:F$318,$A$53:$A$318,"India",$C$53:$C$318,$C6)/'Shared Summary by Dept_US$'!$B$31+SUMIFS(F$53:F$318,$A$53:$A$318,"INDO",$C$53:$C$318,$C6)/'Shared Summary by Dept_US$'!$B$32+SUMIFS(F$53:F$318,$A$53:$A$318,"BD",$C$53:$C$318,$C6)/'Shared Summary by Dept_US$'!$B$33+SUMIFS(F$53:F$318,$A$53:$A$318,"Nepal",$C$53:$C$318,$C6)/'Shared Summary by Dept_US$'!$B$34+SUMIFS(F$53:F$318,$A$53:$A$318,"US",$C$53:$C$318,$C6)/'Shared Summary by Dept_US$'!$B$35 -> 0 | G6: =SUMIFS(G$53:G$318,$A$53:$A$318,"India",$C$53:$C$318,$C6)/'Shared Summary by Dept_US$'!$B$31+SUMIFS(G$53:G$318,$A$53:$A$318,"INDO",$C$53:$C$318,$C6)/'Shared Summary by Dept_US$'!$B$32+SUMIFS(G$53:G$318,$A$53:$A$318,"BD",$C$53:$C$318,$C6)/'Shared Summary by Dept_US$'!$B$33+SUMIFS(G$53:G$318,$A$53:$A$318,"Nepal",$C$53:$C$318,$C6)/'Shared Summary by Dept_US$'!$B$34+SUMIFS(G$53:G$318,$A$53:$A$318,"US",$C$53:$C$318,$C6)/'Shared Summary by Dept_US$'!$B$35 -> 0 | H6: =SUMIFS(H$53:H$318,$A$53:$A$318,"India",$C$53:$C$318,$C6)/'Shared Summary by Dept_US$'!$B$31+SUMIFS(H$53:H$318,$A$53:$A$318,"INDO",$C$53:$C$318,$C6)/'Shared Summary by Dept_US$'!$B$32+SUMIFS(H$53:H$318,$A$53:$A$318,"BD",$C$53:$C$318,$C6)/'Shared Summary by Dept_US$'!$B$33+SUMIFS(H$53:H$318,$A$53:$A$318,"Nepal",$C$53:$C$318,$C6)/'Shared Summary by Dept_US$'!$B$34+SUMIFS(H$53:H$318,$A$53:$A$318,"US",$C$53:$C$318,$C6)/'Shared Summary by Dept_US$'!$B$35 -> 0 | I6: =SUMIFS(I$53:I$318,$A$53:$A$318,"India",$C$53:$C$318,$C6)/'Shared Summary by Dept_US$'!$B$31+SUMIFS(I$53:I$318,$A$53:$A$318,"INDO",$C$53:$C$318,$C6)/'Shared Summary by Dept_US$'!$B$32+SUMIFS(I$53:I$318,$A$53:$A$318,"BD",$C$53:$C$318,$C6)/'Shared Summary by Dept_US$'!$B$33+SUMIFS(I$53:I$318,$A$53:$A$318,"Nepal",$C$53:$C$318,$C6)/'Shared Summary by Dept_US$'!$B$34+SUMIFS(I$53:I$318,$A$53:$A$318,"US",$C$53:$C$318,$C6)/'Shared Summary by Dept_US$'!$B$35 -> 0 | J6: =SUMIFS(J$53:J$318,$A$53:$A$318,"India",$C$53:$C$318,$C6)/'Shared Summary by Dept_US$'!$B$31+SUMIFS(J$53:J$318,$A$53:$A$318,"INDO",$C$53:$C$318,$C6)/'Shared Summary by Dept_US$'!$B$32+SUMIFS(J$53:J$318,$A$53:$A$318,"BD",$C$53:$C$318,$C6)/'Shared Summary by Dept_US$'!$B$33+SUMIFS(J$53:J$318,$A$53:$A$318,"Nepal",$C$53:$C$318,$C6)/'Shared Summary by Dept_US$'!$B$34+SUMIFS(J$53:J$318,$A$53:$A$318,"US",$C$53:$C$318,$C6)/'Shared Summary by Dept_US$'!$B$35 -> 0 | K6: =SUMIFS(K$53:K$318,$A$53:$A$318,"India",$C$53:$C$318,$C6)/'Shared Summary by Dept_US$'!$B$31+SUMIFS(K$53:K$318,$A$53:$A$318,"INDO",$C$53:$C$318,$C6)/'Shared Summary by Dept_US$'!$B$32+SUMIFS(K$53:K$318,$A$53:$A$318,"BD",$C$53:$C$318,$C6)/'Shared Summary by Dept_US$'!$B$33+SUMIFS(K$53:K$318,$A$53:$A$318,"Nepal",$C$53:$C$318,$C6)/'Shared Summary by Dept_US$'!$B$34+SUMIFS(K$53:K$318,$A$53:$A$318,"US",$C$53:$C$318,$C6)/'Shared Summary by Dept_US$'!$B$35 -> 0 | L6: =SUMIFS(L$53:L$318,$A$53:$A$318,"India",$C$53:$C$318,$C6)/'Shared Summary by Dept_US$'!$B$31+SUMIFS(L$53:L$318,$A$53:$A$318,"INDO",$C$53:$C$318,$C6)/'Shared Summary by Dept_US$'!$B$32+SUMIFS(L$53:L$318,$A$53:$A$318,"BD",$C$53:$C$318,$C6)/'Shared Summary by Dept_US$'!$B$33+SUMIFS(L$53:L$318,$A$53:$A$318,"Nepal",$C$53:$C$318,$C6)/'Shared Summary by Dept_US$'!$B$34+SUMIFS(L$53:L$318,$A$53:$A$318,"US",$C$53:$C$318,$C6)/'Shared Summary by Dept_US$'!$B$35 -> 0 | M6: =SUMIFS(M$53:M$318,$A$53:$A$318,"India",$C$53:$C$318,$C6)/'Shared Summary by Dept_US$'!$B$31+SUMIFS(M$53:M$318,$A$53:$A$318,"INDO",$C$53:$C$318,$C6)/'Shared Summary by Dept_US$'!$B$32+SUMIFS(M$53:M$318,$A$53:$A$318,"BD",$C$53:$C$318,$C6)/'Shared Summary by Dept_US$'!$B$33+SUMIFS(M$53:M$318,$A$53:$A$318,"Nepal",$C$53:$C$318,$C6)/'Shared Summary by Dept_US$'!$B$34+SUMIFS(M$53:M$318,$A$53:$A$318,"US",$C$53:$C$318,$C6)/'Shared Summary by Dept_US$'!$B$35 -> 0 | ... Q6: =SUMIFS(Q$53:Q$318,$A$53:$A$318,"India",$C$53:$C$318,$C6)/'Shared Summary by Dept_US$'!$B$31+SUMIFS(Q$53:Q$318,$A$53:$A$318,"INDO",$C$53:$C$318,$C6)/'Shared Summary by Dept_US$'!$B$32+SUMIFS(Q$53:Q$318,$A$53:$A$318,"BD",$C$53:$C$318,$C6)/'Shared Summary by Dept_US$'!$B$33+SUMIFS(Q$53:Q$318,$A$53:$A$318,"Nepal",$C$53:$C$318,$C6)/'Shared Summary by Dept_US$'!$B$34+SUMIFS(Q$53:Q$318,$A$53:$A$318,"US",$C$53:$C$318,$C6)/'Shared Summary by Dept_US$'!$B$35 -> 0
A7: Digital product | B7: Other Staff Expenses | C7: Staff Training, Learning & Development Exp | D7: 91302 | E7: =SUM(F7:Q7) -> 0 | F7: =SUMIFS(F$53:F$318,$A$53:$A$318,"India",$C$53:$C$318,$C7)/'Shared Summary by Dept_US$'!$B$31+SUMIFS(F$53:F$318,$A$53:$A$318,"INDO",$C$53:$C$318,$C7)/'Shared Summary by Dept_US$'!$B$32+SUMIFS(F$53:F$318,$A$53:$A$318,"BD",$C$53:$C$318,$C7)/'Shared Summary by Dept_US$'!$B$33+SUMIFS(F$53:F$318,$A$53:$A$318,"Nepal",$C$53:$C$318,$C7)/'Shared Summary by Dept_US$'!$B$34+SUMIFS(F$53:F$318,$A$53:$A$318,"US",$C$53:$C$318,$C7)/'Shared Summary by Dept_US$'!$B$35 -> 0 | G7: =SUMIFS(G$53:G$318,$A$53:$A$318,"India",$C$53:$C$318,$C7)/'Shared Summary by Dept_US$'!$B$31+SUMIFS(G$53:G$318,$A$53:$A$318,"INDO",$C$53:$C$318,$C7)/'Shared Summary by Dept_US$'!$B$32+SUMIFS(G$53:G$318,$A$53:$A$318,"BD",$C$53:$C$318,$C7)/'Shared Summary by Dept_US$'!$B$33+SUMIFS(G$53:G$318,$A$53:$A$318,"Nepal",$C$53:$C$318,$C7)/'Shared Summary by Dept_US$'!$B$34+SUMIFS(G$53:G$318,$A$53:$A$318,"US",$C$53:$C$318,$C7)/'Shared Summary by Dept_US$'!$B$35 -> 0 | H7: =SUMIFS(H$53:H$318,$A$53:$A$318,"India",$C$53:$C$318,$C7)/'Shared Summary by Dept_US$'!$B$31+SUMIFS(H$53:H$318,$A$53:$A$318,"INDO",$C$53:$C$318,$C7)/'Shared Summary by Dept_US$'!$B$32+SUMIFS(H$53:H$318,$A$53:$A$318,"BD",$C$53:$C$318,$C7)/'Shared Summary by Dept_US$'!$B$33+SUMIFS(H$53:H$318,$A$53:$A$318,"Nepal",$C$53:$C$318,$C7)/'Shared Summary by Dept_US$'!$B$34+SUMIFS(H$53:H$318,$A$53:$A$318,"US",$C$53:$C$318,$C7)/'Shared Summary by Dept_US$'!$B$35 -> 0 | I7: =SUMIFS(I$53:I$318,$A$53:$A$318,"India",$C$53:$C$318,$C7)/'Shared Summary by Dept_US$'!$B$31+SUMIFS(I$53:I$318,$A$53:$A$318,"INDO",$C$53:$C$318,$C7)/'Shared Summary by Dept_US$'!$B$32+SUMIFS(I$53:I$318,$A$53:$A$318,"BD",$C$53:$C$318,$C7)/'Shared Summary by Dept_US$'!$B$33+SUMIFS(I$53:I$318,$A$53:$A$318,"Nepal",$C$53:$C$318,$C7)/'Shared Summary by Dept_US$'!$B$34+SUMIFS(I$53:I$318,$A$53:$A$318,"US",$C$53:$C$318,$C7)/'Shared Summary by Dept_US$'!$B$35 -> 0 | J7: =SUMIFS(J$53:J$318,$A$53:$A$318,"India",$C$53:$C$318,$C7)/'Shared Summary by Dept_US$'!$B$31+SUMIFS(J$53:J$318,$A$53:$A$318,"INDO",$C$53:$C$318,$C7)/'Shared Summary by Dept_US$'!$B$32+SUMIFS(J$53:J$318,$A$53:$A$318,"BD",$C$53:$C$318,$C7)/'Shared Summary by Dept_US$'!$B$33+SUMIFS(J$53:J$318,$A$53:$A$318,"Nepal",$C$53:$C$318,$C7)/'Shared Summary by Dept_US$'!$B$34+SUMIFS(J$53:J$318,$A$53:$A$318,"US",$C$53:$C$318,$C7)/'Shared Summary by Dept_US$'!$B$35 -> 0 | K7: =SUMIFS(K$53:K$318,$A$53:$A$318,"India",$C$53:$C$318,$C7)/'Shared Summary by Dept_US$'!$B$31+SUMIFS(K$53:K$318,$A$53:$A$318,"INDO",$C$53:$C$318,$C7)/'Shared Summary by Dept_US$'!$B$32+SUMIFS(K$53:K$318,$A$53:$A$318,"BD",$C$53:$C$318,$C7)/'Shared Summary by Dept_US$'!$B$33+SUMIFS(K$53:K$318,$A$53:$A$318,"Nepal",$C$53:$C$318,$C7)/'Shared Summary by Dept_US$'!$B$34+SUMIFS(K$53:K$318,$A$53:$A$318,"US",$C$53:$C$318,$C7)/'Shared Summary by Dept_US$'!$B$35 -> 0 | L7: =SUMIFS(L$53:L$318,$A$53:$A$318,"India",$C$53:$C$318,$C7)/'Shared Summary by Dept_US$'!$B$31+SUMIFS(L$53:L$318,$A$53:$A$318,"INDO",$C$53:$C$318,$C7)/'Shared Summary by Dept_US$'!$B$32+SUMIFS(L$53:L$318,$A$53:$A$318,"BD",$C$53:$C$318,$C7)/'Shared Summary by Dept_US$'!$B$33+SUMIFS(L$53:L$318,$A$53:$A$318,"Nepal",$C$53:$C$318,$C7)/'Shared Summary by Dept_US$'!$B$34+SUMIFS(L$53:L$318,$A$53:$A$318,"US",$C$53:$C$318,$C7)/'Shared Summary by Dept_US$'!$B$35 -> 0 | M7: =SUMIFS(M$53:M$318,$A$53:$A$318,"India",$C$53:$C$318,$C7)/'Shared Summary by Dept_US$'!$B$31+SUMIFS(M$53:M$318,$A$53:$A$318,"INDO",$C$53:$C$318,$C7)/'Shared Summary by Dept_US$'!$B$32+SUMIFS(M$53:M$318,$A$53:$A$318,"BD",$C$53:$C$318,$C7)/'Shared Summary by Dept_US$'!$B$33+SUMIFS(M$53:M$318,$A$53:$A$318,"Nepal",$C$53:$C$318,$C7)/'Shared Summary by Dept_US$'!$B$34+SUMIFS(M$53:M$318,$A$53:$A$318,"US",$C$53:$C$318,$C7)/'Shared Summary by Dept_US$'!$B$35 -> 0 | ... Q7: =SUMIFS(Q$53:Q$318,$A$53:$A$318,"India",$C$53:$C$318,$C7)/'Shared Summary by Dept_US$'!$B$31+SUMIFS(Q$53:Q$318,$A$53:$A$318,"INDO",$C$53:$C$318,$C7)/'Shared Summary by Dept_US$'!$B$32+SUMIFS(Q$53:Q$318,$A$53:$A$318,"BD",$C$53:$C$318,$C7)/'Shared Summary by Dept_US$'!$B$33+SUMIFS(Q$53:Q$318,$A$53:$A$318,"Nepal",$C$53:$C$318,$C7)/'Shared Summary by Dept_US$'!$B$34+SUMIFS(Q$53:Q$318,$A$53:$A$318,"US",$C$53:$C$318,$C7)/'Shared Summary by Dept_US$'!$B$35 -> 0
A8: Digital product | B8: Other Staff Expenses | C8: Recruitment Expenses | D8: 91303 | E8: =SUM(F8:Q8) -> 0 | F8: =SUMIFS(F$53:F$318,$A$53:$A$318,"India",$C$53:$C$318,$C8)/'Shared Summary by Dept_US$'!$B$31+SUMIFS(F$53:F$318,$A$53:$A$318,"INDO",$C$53:$C$318,$C8)/'Shared Summary by Dept_US$'!$B$32+SUMIFS(F$53:F$318,$A$53:$A$318,"BD",$C$53:$C$318,$C8)/'Shared Summary by Dept_US$'!$B$33+SUMIFS(F$53:F$318,$A$53:$A$318,"Nepal",$C$53:$C$318,$C8)/'Shared Summary by Dept_US$'!$B$34+SUMIFS(F$53:F$318,$A$53:$A$318,"US",$C$53:$C$318,$C8)/'Shared Summary by Dept_US$'!$B$35 -> 0 | G8: =SUMIFS(G$53:G$318,$A$53:$A$318,"India",$C$53:$C$318,$C8)/'Shared Summary by Dept_US$'!$B$31+SUMIFS(G$53:G$318,$A$53:$A$318,"INDO",$C$53:$C$318,$C8)/'Shared Summary by Dept_US$'!$B$32+SUMIFS(G$53:G$318,$A$53:$A$318,"BD",$C$53:$C$318,$C8)/'Shared Summary by Dept_US$'!$B$33+SUMIFS(G$53:G$318,$A$53:$A$318,"Nepal",$C$53:$C$318,$C8)/'Shared Summary by Dept_US$'!$B$34+SUMIFS(G$53:G$318,$A$53:$A$318,"US",$C$53:$C$318,$C8)/'Shared Summary by Dept_US$'!$B$35 -> 0 | H8: =SUMIFS(H$53:H$318,$A$53:$A$318,"India",$C$53:$C$318,$C8)/'Shared Summary by Dept_US$'!$B$31+SUMIFS(H$53:H$318,$A$53:$A$318,"INDO",$C$53:$C$318,$C8)/'Shared Summary by Dept_US$'!$B$32+SUMIFS(H$53:H$318,$A$53:$A$318,"BD",$C$53:$C$318,$C8)/'Shared Summary by Dept_US$'!$B$33+SUMIFS(H$53:H$318,$A$53:$A$318,"Nepal",$C$53:$C$318,$C8)/'Shared Summary by Dept_US$'!$B$34+SUMIFS(H$53:H$318,$A$53:$A$318,"US",$C$53:$C$318,$C8)/'Shared Summary by Dept_US$'!$B$35 -> 0 | I8: =SUMIFS(I$53:I$318,$A$53:$A$318,"India",$C$53:$C$318,$C8)/'Shared Summary by Dept_US$'!$B$31+SUMIFS(I$53:I$318,$A$53:$A$318,"INDO",$C$53:$C$318,$C8)/'Shared Summary by Dept_US$'!$B$32+SUMIFS(I$53:I$318,$A$53:$A$318,"BD",$C$53:$C$318,$C8)/'Shared Summary by Dept_US$'!$B$33+SUMIFS(I$53:I$318,$A$53:$A$318,"Nepal",$C$53:$C$318,$C8)/'Shared Summary by Dept_US$'!$B$34+SUMIFS(I$53:I$318,$A$53:$A$318,"US",$C$53:$C$318,$C8)/'Shared Summary by Dept_US$'!$B$35 -> 0 | J8: =SUMIFS(J$53:J$318,$A$53:$A$318,"India",$C$53:$C$318,$C8)/'Shared Summary by Dept_US$'!$B$31+SUMIFS(J$53:J$318,$A$53:$A$318,"INDO",$C$53:$C$318,$C8)/'Shared Summary by Dept_US$'!$B$32+SUMIFS(J$53:J$318,$A$53:$A$318,"BD",$C$53:$C$318,$C8)/'Shared Summary by Dept_US$'!$B$33+SUMIFS(J$53:J$318,$A$53:$A$318,"Nepal",$C$53:$C$318,$C8)/'Shared Summary by Dept_US$'!$B$34+SUMIFS(J$53:J$318,$A$53:$A$318,"US",$C$53:$C$318,$C8)/'Shared Summary by Dept_US$'!$B$35 -> 0 | K8: =SUMIFS(K$53:K$318,$A$53:$A$318,"India",$C$53:$C$318,$C8)/'Shared Summary by Dept_US$'!$B$31+SUMIFS(K$53:K$318,$A$53:$A$318,"INDO",$C$53:$C$318,$C8)/'Shared Summary by Dept_US$'!$B$32+SUMIFS(K$53:K$318,$A$53:$A$318,"BD",$C$53:$C$318,$C8)/'Shared Summary by Dept_US$'!$B$33+SUMIFS(K$53:K$318,$A$53:$A$318,"Nepal",$C$53:$C$318,$C8)/'Shared Summary by Dept_US$'!$B$34+SUMIFS(K$53:K$318,$A$53:$A$318,"US",$C$53:$C$318,$C8)/'Shared Summary by Dept_US$'!$B$35 -> 0 | L8: =SUMIFS(L$53:L$318,$A$53:$A$318,"India",$C$53:$C$318,$C8)/'Shared Summary by Dept_US$'!$B$31+SUMIFS(L$53:L$318,$A$53:$A$318,"INDO",$C$53:$C$318,$C8)/'Shared Summary by Dept_US$'!$B$32+SUMIFS(L$53:L$318,$A$53:$A$318,"BD",$C$53:$C$318,$C8)/'Shared Summary by Dept_US$'!$B$33+SUMIFS(L$53:L$318,$A$53:$A$318,"Nepal",$C$53:$C$318,$C8)/'Shared Summary by Dept_US$'!$B$34+SUMIFS(L$53:L$318,$A$53:$A$318,"US",$C$53:$C$318,$C8)/'Shared Summary by Dept_US$'!$B$35 -> 0 | M8: =SUMIFS(M$53:M$318,$A$53:$A$318,"India",$C$53:$C$318,$C8)/'Shared Summary by Dept_US$'!$B$31+SUMIFS(M$53:M$318,$A$53:$A$318,"INDO",$C$53:$C$318,$C8)/'Shared Summary by Dept_US$'!$B$32+SUMIFS(M$53:M$318,$A$53:$A$318,"BD",$C$53:$C$318,$C8)/'Shared Summary by Dept_US$'!$B$33+SUMIFS(M$53:M$318,$A$53:$A$318,"Nepal",$C$53:$C$318,$C8)/'Shared Summary by Dept_US$'!$B$34+SUMIFS(M$53:M$318,$A$53:$A$318,"US",$C$53:$C$318,$C8)/'Shared Summary by Dept_US$'!$B$35 -> 0 | ... Q8: =SUMIFS(Q$53:Q$318,$A$53:$A$318,"India",$C$53:$C$318,$C8)/'Shared Summary by Dept_US$'!$B$31+SUMIFS(Q$53:Q$318,$A$53:$A$318,"INDO",$C$53:$C$318,$C8)/'Shared Summary by Dept_US$'!$B$32+SUMIFS(Q$53:Q$318,$A$53:$A$318,"BD",$C$53:$C$318,$C8)/'Shared Summary by Dept_US$'!$B$33+SUMIFS(Q$53:Q$318,$A$53:$A$318,"Nepal",$C$53:$C$318,$C8)/'Shared Summary by Dept_US$'!$B$34+SUMIFS(Q$53:Q$318,$A$53:$A$318,"US",$C$53:$C$318,$C8)/'Shared Summary by Dept_US$'!$B$35 -> 0
A9: Digital product | B9: Resource Persons | C9: Program Resource Consultant (EHA) | D9: 92101 | E9: =SUM(F9:Q9) -> 439613.03 | F9: =SUMIFS(F$53:F$318,$A$53:$A$318,"India",$C$53:$C$318,$C9)/'Shared Summary by Dept_US$'!$B$31+SUMIFS(F$53:F$318,$A$53:$A$318,"INDO",$C$53:$C$318,$C9)/'Shared Summary by Dept_US$'!$B$32+SUMIFS(F$53:F$318,$A$53:$A$318,"BD",$C$53:$C$318,$C9)/'Shared Summary by Dept_US$'!$B$33+SUMIFS(F$53:F$318,$A$53:$A$318,"Nepal",$C$53:$C$318,$C9)/'Shared Summary by Dept_US$'!$B$34+SUMIFS(F$53:F$318,$A$53:$A$318,"US",$C$53:$C$318,$C9)/'Shared Summary by Dept_US$'!$B$35 -> 39300.549 | G9: =SUMIFS(G$53:G$318,$A$53:$A$318,"India",$C$53:$C$318,$C9)/'Shared Summary by Dept_US$'!$B$31+SUMIFS(G$53:G$318,$A$53:$A$318,"INDO",$C$53:$C$318,$C9)/'Shared Summary by Dept_US$'!$B$32+SUMIFS(G$53:G$318,$A$53:$A$318,"BD",$C$53:$C$318,$C9)/'Shared Summary by Dept_US$'!$B$33+SUMIFS(G$53:G$318,$A$53:$A$318,"Nepal",$C$53:$C$318,$C9)/'Shared Summary by Dept_US$'!$B$34+SUMIFS(G$53:G$318,$A$53:$A$318,"US",$C$53:$C$318,$C9)/'Shared Summary by Dept_US$'!$B$35 -> 37729.916 | H9: =SUMIFS(H$53:H$318,$A$53:$A$318,"India",$C$53:$C$318,$C9)/'Shared Summary by Dept_US$'!$B$31+SUMIFS(H$53:H$318,$A$53:$A$318,"INDO",$C$53:$C$318,$C9)/'Shared Summary by Dept_US$'!$B$32+SUMIFS(H$53:H$318,$A$53:$A$318,"BD",$C$53:$C$318,$C9)/'Shared Summary by Dept_US$'!$B$33+SUMIFS(H$53:H$318,$A$53:$A$318,"Nepal",$C$53:$C$318,$C9)/'Shared Summary by Dept_US$'!$B$34+SUMIFS(H$53:H$318,$A$53:$A$318,"US",$C$53:$C$318,$C9)/'Shared Summary by Dept_US$'!$B$35 -> 36849.49 | I9: =SUMIFS(I$53:I$318,$A$53:$A$318,"India",$C$53:$C$318,$C9)/'Shared Summary by Dept_US$'!$B$31+SUMIFS(I$53:I$318,$A$53:$A$318,"INDO",$C$53:$C$318,$C9)/'Shared Summary by Dept_US$'!$B$32+SUMIFS(I$53:I$318,$A$53:$A$318,"BD",$C$53:$C$318,$C9)/'Shared Summary by Dept_US$'!$B$33+SUMIFS(I$53:I$318,$A$53:$A$318,"Nepal",$C$53:$C$318,$C9)/'Shared Summary by Dept_US$'!$B$34+SUMIFS(I$53:I$318,$A$53:$A$318,"US",$C$53:$C$318,$C9)/'Shared Summary by Dept_US$'!$B$35 -> 34516.168 | J9: =SUMIFS(J$53:J$318,$A$53:$A$318,"India",$C$53:$C$318,$C9)/'Shared Summary by Dept_US$'!$B$31+SUMIFS(J$53:J$318,$A$53:$A$318,"INDO",$C$53:$C$318,$C9)/'Shared Summary by Dept_US$'!$B$32+SUMIFS(J$53:J$318,$A$53:$A$318,"BD",$C$53:$C$318,$C9)/'Shared Summary by Dept_US$'!$B$33+SUMIFS(J$53:J$318,$A$53:$A$318,"Nepal",$C$53:$C$318,$C9)/'Shared Summary by Dept_US$'!$B$34+SUMIFS(J$53:J$318,$A$53:$A$318,"US",$C$53:$C$318,$C9)/'Shared Summary by Dept_US$'!$B$35 -> 36897.48 | K9: =SUMIFS(K$53:K$318,$A$53:$A$318,"India",$C$53:$C$318,$C9)/'Shared Summary by Dept_US$'!$B$31+SUMIFS(K$53:K$318,$A$53:$A$318,"INDO",$C$53:$C$318,$C9)/'Shared Summary by Dept_US$'!$B$32+SUMIFS(K$53:K$318,$A$53:$A$318,"BD",$C$53:$C$318,$C9)/'Shared Summary by Dept_US$'!$B$33+SUMIFS(K$53:K$318,$A$53:$A$318,"Nepal",$C$53:$C$318,$C9)/'Shared Summary by Dept_US$'!$B$34+SUMIFS(K$53:K$318,$A$53:$A$318,"US",$C$53:$C$318,$C9)/'Shared Summary by Dept_US$'!$B$35 -> 35766.168 | L9: =SUMIFS(L$53:L$318,$A$53:$A$318,"India",$C$53:$C$318,$C9)/'Shared Summary by Dept_US$'!$B$31+SUMIFS(L$53:L$318,$A$53:$A$318,"INDO",$C$53:$C$318,$C9)/'Shared Summary by Dept_US$'!$B$32+SUMIFS(L$53:L$318,$A$53:$A$318,"BD",$C$53:$C$318,$C9)/'Shared Summary by Dept_US$'!$B$33+SUMIFS(L$53:L$318,$A$53:$A$318,"Nepal",$C$53:$C$318,$C9)/'Shared Summary by Dept_US$'!$B$34+SUMIFS(L$53:L$318,$A$53:$A$318,"US",$C$53:$C$318,$C9)/'Shared Summary by Dept_US$'!$B$35 -> 35825.543 | M9: =SUMIFS(M$53:M$318,$A$53:$A$318,"India",$C$53:$C$318,$C9)/'Shared Summary by Dept_US$'!$B$31+SUMIFS(M$53:M$318,$A$53:$A$318,"INDO",$C$53:$C$318,$C9)/'Shared Summary by Dept_US$'!$B$32+SUMIFS(M$53:M$318,$A$53:$A$318,"BD",$C$53:$C$318,$C9)/'Shared Summary by Dept_US$'!$B$33+SUMIFS(M$53:M$318,$A$53:$A$318,"Nepal",$C$53:$C$318,$C9)/'Shared Summary by Dept_US$'!$B$34+SUMIFS(M$53:M$318,$A$53:$A$318,"US",$C$53:$C$318,$C9)/'Shared Summary by Dept_US$'!$B$35 -> 36450.543 | ... Q9: =SUMIFS(Q$53:Q$318,$A$53:$A$318,"India",$C$53:$C$318,$C9)/'Shared Summary by Dept_US$'!$B$31+SUMIFS(Q$53:Q$318,$A$53:$A$318,"INDO",$C$53:$C$318,$C9)/'Shared Summary by Dept_US$'!$B$32+SUMIFS(Q$53:Q$318,$A$53:$A$318,"BD",$C$53:$C$318,$C9)/'Shared Summary by Dept_US$'!$B$33+SUMIFS(Q$53:Q$318,$A$53:$A$318,"Nepal",$C$53:$C$318,$C9)/'Shared Summary by Dept_US$'!$B$34+SUMIFS(Q$53:Q$318,$A$53:$A$318,"US",$C$53:$C$318,$C9)/'Shared Summary by Dept_US$'!$B$35 -> 36569.293
A10: Digital product | B10: Travel & Lodging Expenses | C10: Hotel Accomodation | D10: 93101 | E10: =SUM(F10:Q10) -> 15450.467 | F10: =SUMIFS(F$53:F$318,$A$53:$A$318,"India",$C$53:$C$318,$C10)/'Shared Summary by Dept_US$'!$B$31+SUMIFS(F$53:F$318,$A$53:$A$318,"INDO",$C$53:$C$318,$C10)/'Shared Summary by Dept_US$'!$B$32+SUMIFS(F$53:F$318,$A$53:$A$318,"BD",$C$53:$C$318,$C10)/'Shared Summary by Dept_US$'!$B$33+SUMIFS(F$53:F$318,$A$53:$A$318,"Nepal",$C$53:$C$318,$C10)/'Shared Summary by Dept_US$'!$B$34+SUMIFS(F$53:F$318,$A$53:$A$318,"US",$C$53:$C$318,$C10)/'Shared Summary by Dept_US$'!$B$35 -> 325 | G10: =SUMIFS(G$53:G$318,$A$53:$A$318,"India",$C$53:$C$318,$C10)/'Shared Summary by Dept_US$'!$B$31+SUMIFS(G$53:G$318,$A$53:$A$318,"INDO",$C$53:$C$318,$C10)/'Shared Summary by Dept_US$'!$B$32+SUMIFS(G$53:G$318,$A$53:$A$318,"BD",$C$53:$C$318,$C10)/'Shared Summary by Dept_US$'!$B$33+SUMIFS(G$53:G$318,$A$53:$A$318,"Nepal",$C$53:$C$318,$C10)/'Shared Summary by Dept_US$'!$B$34+SUMIFS(G$53:G$318,$A$53:$A$318,"US",$C$53:$C$318,$C10)/'Shared Summary by Dept_US$'!$B$35 -> 700.75431 | H10: =SUMIFS(H$53:H$318,$A$53:$A$318,"India",$C$53:$C$318,$C10)/'Shared Summary by Dept_US$'!$B$31+SUMIFS(H$53:H$318,$A$53:$A$318,"INDO",$C$53:$C$318,$C10)/'Shared Summary by Dept_US$'!$B$32+SUMIFS(H$53:H$318,$A$53:$A$318,"BD",$C$53:$C$318,$C10)/'Shared Summary by Dept_US$'!$B$33+SUMIFS(H$53:H$318,$A$53:$A$318,"Nepal",$C$53:$C$318,$C10)/'Shared Summary by Dept_US$'!$B$34+SUMIFS(H$53:H$318,$A$53:$A$318,"US",$C$53:$C$318,$C10)/'Shared Summary by Dept_US$'!$B$35 -> 1733.4052 | I10: =SUMIFS(I$53:I$318,$A$53:$A$318,"India",$C$53:$C$318,$C10)/'Shared Summary by Dept_US$'!$B$31+SUMIFS(I$53:I$318,$A$53:$A$318,"INDO",$C$53:$C$318,$C10)/'Shared Summary by Dept_US$'!$B$32+SUMIFS(I$53:I$318,$A$53:$A$318,"BD",$C$53:$C$318,$C10)/'Shared Summary by Dept_US$'!$B$33+SUMIFS(I$53:I$318,$A$53:$A$318,"Nepal",$C$53:$C$318,$C10)/'Shared Summary by Dept_US$'!$B$34+SUMIFS(I$53:I$318,$A$53:$A$318,"US",$C$53:$C$318,$C10)/'Shared Summary by Dept_US$'!$B$35 -> 2432.9023 | J10: =SUMIFS(J$53:J$318,$A$53:$A$318,"India",$C$53:$C$318,$C10)/'Shared Summary by Dept_US$'!$B$31+SUMIFS(J$53:J$318,$A$53:$A$318,"INDO",$C$53:$C$318,$C10)/'Shared Summary by Dept_US$'!$B$32+SUMIFS(J$53:J$318,$A$53:$A$318,"BD",$C$53:$C$318,$C10)/'Shared Summary by Dept_US$'!$B$33+SUMIFS(J$53:J$318,$A$53:$A$318,"Nepal",$C$53:$C$318,$C10)/'Shared Summary by Dept_US$'!$B$34+SUMIFS(J$53:J$318,$A$53:$A$318,"US",$C$53:$C$318,$C10)/'Shared Summary by Dept_US$'!$B$35 -> 2699.569 | K10: =SUMIFS(K$53:K$318,$A$53:$A$318,"India",$C$53:$C$318,$C10)/'Shared Summary by Dept_US$'!$B$31+SUMIFS(K$53:K$318,$A$53:$A$318,"INDO",$C$53:$C$318,$C10)/'Shared Summary by Dept_US$'!$B$32+SUMIFS(K$53:K$318,$A$53:$A$318,"BD",$C$53:$C$318,$C10)/'Shared Summary by Dept_US$'!$B$33+SUMIFS(K$53:K$318,$A$53:$A$318,"Nepal",$C$53:$C$318,$C10)/'Shared Summary by Dept_US$'!$B$34+SUMIFS(K$53:K$318,$A$53:$A$318,"US",$C$53:$C$318,$C10)/'Shared Summary by Dept_US$'!$B$35 -> 1425 | L10: =SUMIFS(L$53:L$318,$A$53:$A$318,"India",$C$53:$C$318,$C10)/'Shared Summary by Dept_US$'!$B$31+SUMIFS(L$53:L$318,$A$53:$A$318,"INDO",$C$53:$C$318,$C10)/'Shared Summary by Dept_US$'!$B$32+SUMIFS(L$53:L$318,$A$53:$A$318,"BD",$C$53:$C$318,$C10)/'Shared Summary by Dept_US$'!$B$33+SUMIFS(L$53:L$318,$A$53:$A$318,"Nepal",$C$53:$C$318,$C10)/'Shared Summary by Dept_US$'!$B$34+SUMIFS(L$53:L$318,$A$53:$A$318,"US",$C$53:$C$318,$C10)/'Shared Summary by Dept_US$'!$B$35 -> 1580.6753 | M10: =SUMIFS(M$53:M$318,$A$53:$A$318,"India",$C$53:$C$318,$C10)/'Shared Summary by Dept_US$'!$B$31+SUMIFS(M$53:M$318,$A$53:$A$318,"INDO",$C$53:$C$318,$C10)/'Shared Summary by Dept_US$'!$B$32+SUMIFS(M$53:M$318,$A$53:$A$318,"BD",$C$53:$C$318,$C10)/'Shared Summary by Dept_US$'!$B$33+SUMIFS(M$53:M$318,$A$53:$A$318,"Nepal",$C$53:$C$318,$C10)/'Shared Summary by Dept_US$'!$B$34+SUMIFS(M$53:M$318,$A$53:$A$318,"US",$C$53:$C$318,$C10)/'Shared Summary by Dept_US$'!$B$35 -> 1033.7644 | ... Q10: =SUMIFS(Q$53:Q$318,$A$53:$A$318,"India",$C$53:$C$318,$C10)/'Shared Summary by Dept_US$'!$B$31+SUMIFS(Q$53:Q$318,$A$53:$A$318,"INDO",$C$53:$C$318,$C10)/'Shared Summary by Dept_US$'!$B$32+SUMIFS(Q$53:Q$318,$A$53:$A$318,"BD",$C$53:$C$318,$C10)/'Shared Summary by Dept_US$'!$B$33+SUMIFS(Q$53:Q$318,$A$53:$A$318,"Nepal",$C$53:$C$318,$C10)/'Shared Summary by Dept_US$'!$B$34+SUMIFS(Q$53:Q$318,$A$53:$A$318,"US",$C$53:$C$318,$C10)/'Shared Summary by Dept_US$'!$B$35 -> 487.5
